<?xml version="1.0"?>

<robot name="FourDOF">

  <!-- *************************************************** -->
  <!-- ***************** Kinematic Chain ***************** -->
  <!-- *************************************************** -->
  <!-- <link name="..."> is really a frame!                -->
  <!-- <joint name="..." type="fixed">      is a fixed shift.    -->
  <!-- <joint name="..." type="continuous"> is a revolute joint. -->
  <!-- <joint name="..." type="prismatic">  is a linear   joint. -->
  <!-- Note the 'origin' tag in the joints defines the shift and
       reorientation, i.e. the transform.  For moving joints, this
       happens before the continuous joint rotates around 'axis'. -->

  <!-- Set Origin -->
  <link name="world">
  </link>

  <!-- Shift origin to joint 1 -->
  <joint name="shift0" type="fixed">
    <parent link="world"/>
    <child  link="frame1"/>
    <origin xyz="0 0 0.2" rpy="0 0 0"/>
  </joint>

  <!-- Define Joint 1 -->
  <link name="frame1">
  </link>
  
  <!-- Rotation of Joint 1 -->
  <joint name="theta1" type="continuous">
    <parent link="frame1"/>
    <child  link="frame1prime"/>
    <origin xyz="0 0 0.2" rpy="0 0 0"/>
    <axis   xyz="0 0 1"/>
  </joint>

  <link name="frame1prime">
  </link>

  <joint name="shift1prime" type="fixed">
    <parent link="frame1prime"/>
    <child  link="frame2"/>
    <origin xyz="0 0.2 0" rpy="0 0 0"/>
  </joint>

  <!-- Define Joint 2 -->
  <link name="frame2">
  </link>

  <!-- Shift 1 and Joint 2 in one step... -->
  <joint name="theta2" type="continuous">
    <parent link="frame2"/>
    <child  link="frame2prime"/>
    <origin xyz="0 0.2 0" rpy="0 0 0"/>
    <axis   xyz="0 1 0"/>
  </joint>

  <link name="frame2prime">
  </link>

  <joint name="shift2prime" type="fixed">
    <parent link="frame2prime"/>
    <child  link="frame3"/>
    <origin xyz="0 0 -0.2" rpy="0 0 0"/>
  </joint>

  <link name="frame3">
  </link>

  <!-- Shift 2 and Joint 3 in one step... -->
  <joint name="theta3" type="continuous">
    <parent link="frame3"/>
    <child  link="frame3prime"/>
    <origin xyz="0 0 -0.2" rpy="0 0 0"/>
    <axis   xyz="0 0 -1"/>
  </joint>
  
  <link name="frame3prime">
  </link>

  <joint name="shift3prime" type="fixed">
    <parent link="frame3prime"/>
    <child  link="frame4"/>
    <origin xyz="0 0.2 0" rpy="0 0 0"/>
  </joint>

  <link name="frame4">
  </link>

  <!-- Shift 3 and Joint 4 in one step... -->
  <joint name="theta4" type="continuous">
    <parent link="frame4"/>
    <child  link="frameTip"/>
    <origin xyz="0 0.2 0" rpy="0 0 0"/>
    <axis   xyz="0 1 0"/>
  </joint>
  
  <link name="frameTip">
  </link>

  <!-- *************************************************** -->
  <!-- ****************** Named Colors ******************* -->
  <!-- *************************************************** -->

  <material name="white">    <color rgba="1.00 1.00 1.00 1"/>  </material>
  <material name="gray">     <color rgba="0.60 0.60 0.60 1"/>  </material>
  <material name="table">    <color rgba="0.85 0.77 0.77 1"/>  </material>
  <material name="black">    <color rgba="0.00 0.00 0.00 1"/>  </material>

  <material name="red">      <color rgba="1.00 0.00 0.00 1"/>  </material>
  <material name="green">    <color rgba="0.00 1.00 0.00 1"/>  </material>
  <material name="blue">     <color rgba="0.00 0.00 1.00 1"/>  </material>

  <material name="cyan">     <color rgba="0.00 1.00 1.00 1"/>  </material>
  <material name="magenta">  <color rgba="1.00 0.00 1.00 1"/>  </material>
  <material name="yellow">   <color rgba="1.00 1.00 0.00 1"/>  </material>

  <material name="orange">   <color rgba="1.00 0.65 0.00 1"/>  </material>


  <!-- *************************************************** -->
  <!-- *********** Additional Visual Elements ************ -->
  <!-- *************************************************** -->

</robot>
